Workbook

Sheet Kraftwerksliste_Miri
A1: Teil der Merit-Order? | B1: MaStR-Nr. | C1: ÜNB | D1: Status | E1: Anlagenbetreiber | F1: Anzeige-Name | G1: PLZ der Einheit | H1: Ort der Einheit | I1: Straße und Hausnummer der Einheit | J1: Bundesland der Einheit | K1: Datum der erstmaligen Inbetriebnahme der Einheit | L1: Energieträger | M1: Hauptbrennstoff | N1: Auswertung Energieträger | O1: Wärmeauskopplung (KW) ja/nein | P1: Technologie der Stromerzeugung | Q1: Angenommener Hauptenergieträger | R1: Zuordnung Kraftwerkstyp | S1: Effizienz | T1: Quelle Effizienz | U1: Bruttoleistung [MW] | V1: Netto-Nennleistung (elektrische Wirkleistung) [MW] | W1: Mittlere verfügbare Netto-Nennleistung [MW] | X1: Brennstoffkosten (inkl. Transport) [EUR/MWHth] | Y1: Grenzkosten [EUR/MWHel]
A2: Ja | B2: SEE987512757786 | C2: =VLOOKUP(B2,Tabelle3!A:C,2,FALSE) -> Nord | D2: In Betrieb | E2: ArcelorMittal Eisenhüttenstadt GmbH | F2: IKW Block 8 | G2: 15890 | H2: Eisenhüttenstadt | I2: Jugendstraße 1 | J2: Brandenburg | K2: 19725 | L2: Erdgas | M2: Erdgas, Erdölgas | N2: Erdgas | O2: Ja | P2: Gasturbinen mit nachgeschalteter Dampfturbine | Q2: Erdgas | R2: Gasturbine | S2: 0.33 | T2: Annahme basierend auf DIW (2014) | U2: 89.717 | V2: 88.11 | W2: 76.6557 | X2: 40.69 | Y2: 166.54348
A3: Ja | B3: SEE961788817153 | C3: =VLOOKUP(B3,Tabelle3!A:C,2,FALSE) -> Nord | D3: In Betrieb | E3: BASF Schwarzheide GmbH | F3: DT2 | G3: 01987 | H3: Schwarzheide | I3: Schipkauer Straße 1 | J3: Brandenburg | K3: 35769 | L3: Erdgas | M3: Erdgas, Erdölgas | N3: Erdgas | O3: Nein | P3: Kondensationsmaschine ohne Entnahme | Q3: Erdgas | R3: GuD | S3: 0.513 | T3: OPSD (2020) | U3: 12.3 | V3: 12 | W3: 10.44 | X3: 40.69 | Y3: 107.98996
A4: Ja | B4: SEE971164680486 | C4: =VLOOKUP(B4,Tabelle3!A:C,2,FALSE) -> Nord | D4: In Betrieb | E4: BASF Schwarzheide GmbH | F4: DT1 | G4: 01987 | H4: Schwarzheide | I4: Schipkauer Straße 1 | J4: Brandenburg | K4: 34666 | L4: Erdgas | M4: Erdgas, Erdölgas | N4: Erdgas | O4: Ja | P4: Gegendruckmaschine mit Entnahme | Q4: Erdgas | R4: GuD | S4: 0.513 | T4: OPSD (2020) | U4: 25.84 | V4: 25.517 | W4: 22.19979 | X4: 40.69 | Y4: 107.98996
A5: Ja | B5: SEE918705951896 | C5: =VLOOKUP(B5,Tabelle3!A:C,2,FALSE) -> Nord | D5: In Betrieb | E5: BASF Schwarzheide GmbH | F5: GT2 | G5: 01987 | H5: Schwarzheide | I5: Schipkauer Straße 1 | J5: Brandenburg | K5: 34666 | L5: Erdgas | M5: Erdgas, Erdölgas | N5: Erdgas | O5: Ja | P5: Gasturbinen mit nachgeschalteter Dampfturbine | Q5: Erdgas | R5: Gasturbine | S5: 0.513 | T5: OPSD (2020) | U5: 40.94 | V5: 40.428 | W5: 35.17236 | X5: 40.69 | Y5: 107.48996
A6: Ja | B6: SEE904165703137 | C6: =VLOOKUP(B6,Tabelle3!A:C,2,FALSE) -> Nord | D6: In Betrieb | E6: BASF Schwarzheide GmbH | F6: GT1 | G6: 01987 | H6: Schwarzheide | I6: Schipkauer Straße 1 | J6: Brandenburg | K6: 34666 | L6: Erdgas | M6: Erdgas, Erdölgas | N6: Erdgas | O6: Ja | P6: Gasturbinen mit nachgeschalteter Dampfturbine | Q6: Erdgas | R6: Gasturbine | S6: 0.513 | T6: OPSD (2020) | U6: 52 | V6: 51.35 | W6: 44.6745 | X6: 40.69 | Y6: 107.48996
A7: Ja | B7: SEE963909310185 | C7: Nord | D7: In Betrieb | E7: BEW Berliner Energie und Wärme AG | F7: HKW Moabit Gasturbine 5 | G7: 13353 | H7: Berlin | I7: Friedrich-Krause-Ufer 42278 | J7: Berlin | K7: 26236 | L7: Mineralölprodukte | M7: Heizöl, leicht | N7: Mineralölprodukte | O7: Nein | P7: Gasturbinen ohne Abhitzekessel | Q7: Öl | R7: Öl | S7: 0.3046 | T7: OPSD (2020) | U7: 17 | V7: 17 | W7: 14.45 | X7: 95.89 | Y7: 379.55548
A8: Ja | B8: SEE992645841813 | C8: Nord | D8: In Betrieb | E8: BEW Berliner Energie und Wärme AG | F8: HKW Moabit Gasturbine 6 | G8: 13353 | H8: Berlin | I8: Friedrich-Krause-Ufer 42278 | J8: Berlin | K8: 26264 | L8: Mineralölprodukte | M8: Heizöl, leicht | N8: Mineralölprodukte | O8: Nein | P8: Gasturbinen ohne Abhitzekessel | Q8: Öl | R8: Öl | S8: 0.3046 | T8: OPSD (2020) | U8: 17 | V8: 17 | W8: 14.45 | X8: 95.89 | Y8: 379.55548
A9: Ja | B9: SEE988848971327 | C9: =VLOOKUP(B9,Tabelle3!A:C,2,FALSE) -> Nord | D9: In Betrieb | E9: BEW Berliner Energie und Wärme AG | F9: HKW Reuter, Dampfturbine M | G9: 13599 | H9: Berlin | I9: Otternbuchtstraße 11 | J9: Berlin | K9: 35830 | L9: Wärme | M9: Dampf (zum Beispiel Prozesswärme) | N9: Wärme | O9: Ja | P9: Gegendruckmaschine mit Entnahme | Q9: Sonstige | R9: Sonstige | S9: 0.33 | T9: OPSD (2020) | U9: 36.36 | V9: 36 | W9: 30.6 | X9: 95.59 | Y9: 335.63909
A10: Ja | B10: SEE997719859992 | C10: Nord | D10: In Betrieb | E10: BEW Berliner Energie und Wärme AG | F10: HKW Klingenberg Dampfturbine 1 | G10: 10317 | H10: Berlin | I10: Köpenicker Chaussee 42-45 | J10: Berlin | K10: 29811 | L10: Erdgas | M10: Erdgas, Erdölgas | N10: Erdgas | O10: Ja | P10: Gegendruckmaschine mit Entnahme | Q10: Erdgas | R10: GuD | S10: 0.4037 | T10: OPSD (2020) | U10: 60 | V10: 52 | W10: 45.24 | X10: 40.69 | Y10: 136.82165
A11: Ja | B11: SEE988684097793 | C11: Nord | D11: In Betrieb | E11: BEW Berliner Energie und Wärme AG | F11: HKW Klingenberg Dampfturbine 2 | G11: 10317 | H11: Berlin | I11: Köpenicker Chaussee 42-45 | J11: Berlin | K11: 29914 | L11: Erdgas | M11: Erdgas, Erdölgas | N11: Erdgas | O11: Ja | P11: Gegendruckmaschine mit Entnahme | Q11: Erdgas | R11: GuD | S11: 0.4037 | T11: OPSD (2020) | U11: 64 | V11: 56 | W11: 48.72 | X11: 40.69 | Y11: 136.82165
A12: Ja | B12: SEE965333653821 | C12: Nord | D12: In Betrieb | E12: BEW Berliner Energie und Wärme AG | F12: HKW Klingenberg Dampfturbine 3 | G12: 10317 | H12: Berlin | I12: Köpenicker Chaussee 42-45 | J12: Berlin | K12: 30182 | L12: Erdgas | M12: Erdgas, Erdölgas | N12: Erdgas | O12: Ja | P12: Gegendruckmaschine mit Entnahme | Q12: Erdgas | R12: GuD | S12: 0.4037 | T12: OPSD (2020) | U12: 64 | V12: 56 | W12: 48.72 | X12: 40.69 | Y12: 136.82165
A13: Ja | B13: SEE982928435068 | C13: =VLOOKUP(B13,Tabelle3!A:C,2,FALSE) -> Nord | D13: In Betrieb | E13: BEW Berliner Energie und Wärme AG | F13: GuD Marzahn Dampfturbine | G13: 12681 | H13: Berlin | I13: Allee der Kosmonauten 26 B | J13: Berlin | K13: 43958 | L13: Wärme | M13: Dampf (zum Beispiel Prozesswärme) | N13: Wärme | O13: Ja | P13: Kondensationsmaschine mit Entnahme | Q13: Sonstige | R13: Sonstige | S13: 0.365 | T13: https://www.siemens-energy.com/global/en/offerings/power-generation/gas-turbines/sgt5-2000e.html | U13: 70.5 | V13: 69.3 | W13: 58.905 | X13: 95.59 | Y13: 303.55041
A14: Ja | B14: SEE926090463146 | C14: Nord | D14: In Betrieb | E14: BEW Berliner Energie und Wärme AG | F14: HKW Charlottenburg Gasturbine 4 | G14: 10589 | H14: Berlin | I14: Am Spreebord 5 | J14: Berlin | K14: 27793 | L14: Erdgas | M14: Erdgas, Erdölgas | N14: Erdgas | O14: Ja | P14: Gasturbinen mit Abhitzekessel | Q14: Erdgas | R14: GuD | S14: 0.3575 | T14: OPSD (2020) | U14: 73 | V14: 72 | W14: 62.64 | X14: 40.69 | Y14: 154.30937
A15: Ja | B15: SEE962934119541 | C15: Nord | D15: In Betrieb | E15: BEW Berliner Energie und Wärme AG | F15: HKW Charlottenburg Gasturbine 5 | G15: 10589 | H15: Berlin | I15: Am Spreebord 5 | J15: Berlin | K15: 27992 | L15: Erdgas | M15: Erdgas, Erdölgas | N15: Erdgas | O15: Ja | P15: Gasturbinen mit Abhitzekessel | Q15: Erdgas | R15: GuD | S15: 0.3575 | T15: OPSD (2020) | U15: 73 | V15: 72 | W15: 62.64 | X15: 40.69 | Y15: 154.30937
A16: Ja | B16: SEE981109871657 | C16: Nord | D16: In Betrieb | E16: BEW Berliner Energie und Wärme AG | F16: HKW Moabit Dampfturbine | G16: 13353 | H16: Berlin | I16: Friedrich-Krause-Ufer 42278 | J16: Berlin | K16: 32931 | L16: Steinkohle | M16: Steinkohlen | N16: Steinkohle | O16: Ja | P16: Kondensationsmaschine mit Entnahme | Q16: Steinkohle | R16: Steinkohle | S16: 0.4 | T16: OPSD (2020) | U16: 100 | V16: 89 | W16: 71.2 | X16: 15.55 | Y16: 98.602375
A17: Ja | B17: SEE929077603696 | C17: =VLOOKUP(B17,Tabelle3!A:C,2,FALSE) -> Nord | D17: In Betrieb | E17: BEW Berliner Energie und Wärme AG | F17: GuD Lichterfelde Dampfturbine | G17: 12207 | H17: Berlin | I17: Ostpreußendamm 61 | J17: Berlin | K17: 43566 | L17: Wärme | M17: Dampf (zum Beispiel Prozesswärme) | N17: Wärme | O17: Ja | P17: Kondensationsmaschine mit Entnahme | Q17: Sonstige | R17: Sonstige | S17: 0.4059 | T17: OPSD (2020) | U17: 125 | V17: 115 | W17: 97.75 | X17: 95.59 | Y17: 273.0643
A18: Ja | B18: SEE992187994404 | C18: =VLOOKUP(B18,Tabelle3!A:C,2,FALSE) -> Nord | D18: In Betrieb | E18: BEW Berliner Energie und Wärme AG | F18: HKW Mitte Dampfturbine | G18: 10179 | H18: Berlin | I18: Köpenicker Straße 60 | J18: Berlin | K18: 35681 | L18: Wärme | M18: Dampf (zum Beispiel Prozesswärme) | N18: Wärme | O18: Ja | P18: Gegendruckmaschine mit Entnahme | Q18: Sonstige | R18: Sonstige | S18: 0.49 | T18: OPSD (2020) | U18: 117.16 | V18: 116 | W18: 98.6 | X18: 95.59 | Y18: 226.36918
A19: Ja | B19: SEE904819420762 | C19: =VLOOKUP(B19,Tabelle3!A:C,2,FALSE) -> Nord | D19: In Betrieb | E19: BEW Berliner Energie und Wärme AG | F19: HKW Mitte Gasturbine 1 | G19: 10179 | H19: Berlin | I19: Köpenicker Straße 60 | J19: Berlin | K19: 35681 | L19: Erdgas | M19: Erdgas, Erdölgas | N19: Erdgas | O19: Ja | P19: Gasturbinen mit Abhitzekessel | Q19: Erdgas | R19: GuD | S19: 0.49 | T19: OPSD (2020) | U19: 172 | V19: 164 | W19: 142.68 | X19: 40.69 | Y19: 112.98847
A20: Ja | B20: SEE948541471333 | C20: =VLOOKUP(B20,Tabelle3!A:C,2,FALSE) -> Nord | D20: In Betrieb | E20: BEW Berliner Energie und Wärme AG | F20: HKW Mitte Gasturbine 2 | G20: 10179 | H20: Berlin | I20: Köpenicker Straße 60 | J20: Berlin | K20: 35681 | L20: Erdgas | M20: Erdgas, Erdölgas | N20: Erdgas | O20: Ja | P20: Gasturbinen mit Abhitzekessel | Q20: Erdgas | R20: GuD | S20: 0.49 | T20: OPSD (2020) | U20: 172 | V20: 164 | W20: 142.68 | X20: 40.69 | Y20: 112.98847
A21: Ja | B21: SEE923401813959 | C21: =VLOOKUP(B21,Tabelle3!A:C,2,FALSE) -> Nord | D21: In Betrieb | E21: BEW Berliner Energie und Wärme AG | F21: GuD Lichterfelde Gasturbine | G21: 12207 | H21: Berlin | I21: Ostpreußendamm 61 | J21: Berlin | K21: 43566 | L21: Erdgas | M21: Erdgas, Erdölgas | N21: Erdgas | O21: Ja | P21: Kondensationsmaschine mit Entnahme | Q21: Erdgas | R21: GuD | S21: 0.4059 | T21: OPSD (2020) | U21: 190 | V21: 185 | W21: 160.95 | X21: 40.69 | Y21: 136.0882
A22: Ja | B22: SEE937536026146 | C22: =VLOOKUP(B22,Tabelle3!A:C,2,FALSE) -> Nord | D22: In Betrieb | E22: BEW Berliner Energie und Wärme AG | F22: GuD Marzahn Gasturbine | G22: 12681 | H22: Berlin | I22: Allee der Kosmonauten 26 B | J22: Berlin | K22: 43958 | L22: Erdgas | M22: Erdgas, Erdölgas | N22: Erdgas | O22: Ja | P22: Gasturbinen mit nachgeschalteter Dampfturbine | Q22: Erdgas | R22: Gasturbine | S22: 0.6 | T22: eigene Annahme | U22: 196 | V22: 189.5 | W22: 164.865 | X22: 40.69 | Y22: 92.048917
A23: Ja | B23: SEE974883809046 | C23: Nord | D23: In Betrieb | E23: BEW Berliner Energie und Wärme AG | F23: HKW Reuter West Dampfturbine E | G23: 13599 | H23: Berlin | I23: Großer Spreering 5 | J23: Berlin | K23: 32356 | L23: Steinkohle | M23: Steinkohlen | N23: Steinkohle | O23: Ja | P23: Kondensationsmaschine mit Entnahme | Q23: Steinkohle | R23: Steinkohle | S23: 0.4 | T23: OPSD (2020) | U23: 300 | V23: 282 | W23: 225.6 | X23: 15.55 | Y23: 98.602375
A24: Ja | B24: SEE989328541450 | C24: Nord | D24: In Betrieb | E24: BEW Berliner Energie und Wärme AG | F24: HKW Reuter West Dampfturbine D | G24: 13599 | H24: Berlin | I24: Großer Spreering 5 | J24: Berlin | K24: 32125 | L24: Steinkohle | M24: Steinkohlen | N24: Steinkohle | O24: Ja | P24: Kondensationsmaschine mit Entnahme | Q24: Steinkohle | R24: Steinkohle | S24: 0.4 | T24: OPSD (2020) | U24: 300 | V24: 282 | W24: 225.6 | X24: 15.55 | Y24: 98.602375
A25: Ja | B25: SEE941053107073 | C25: =VLOOKUP(B25,Tabelle3!A:C,2,FALSE) -> Nord | D25: In Betrieb | E25: Cargill Deutschland GmbH | F25: Stromerzeugung Barby | G25: 39249 | H25: Barby | I25: Monplaisirstraße 22 | J25: Sachsen-Anhalt | K25: 41403 | L25: Erdgas | M25: Erdgas, Erdölgas | N25: Erdgas | O25: Ja | P25: Gasturbinen mit Abhitzekessel | Q25: Erdgas | R25: GuD | S25: 0.3784 | T25: OPSD (2020) | U25: 17.951 | V25: 17.78 | W25: 15.4686 | X25: 40.69 | Y25: 145.86932
A26: Ja | B26: SEE905257392765 | C26: =VLOOKUP(B26,Tabelle3!A:C,2,FALSE) -> Nord | D26: In Betrieb | E26: Cosun Beet Company GmbH & Co. KG | F26: Kesselhaus | G26: 17389 | H26: Anklam | I26: Bluthsluster Straße 24 | J26: Mecklenburg-Vorpommern | K26: 34238 | L26: Erdgas | M26: Erdgas, Erdölgas | N26: Erdgas | O26: Ja | P26: Gegendruckmaschine mit Entnahme | Q26: Erdgas | R26: GuD | S26: 0.3773 | T26: OPSD (2020) | U26: 16 | V26: 15 | W26: 13.05 | X26: 40.69 | Y26: 146.29022
A27: Ja | B27: SEE907667929555 | C27: =VLOOKUP(B27,Tabelle3!A:C,2,FALSE) -> Nord | D27: In Betrieb | E27: DREWAG - Stadtwerke Dresden GmbH | F27: HKW Dresden-Nord | G27: 01099 | H27: Dresden | I27: Hermann-Mende-Straße 2 | J27: Sachsen | K27: 43441 | L27: Erdgas | M27: Erdgas, Erdölgas | N27: Erdgas | O27: Ja | P27: Gasturbinen mit Abhitzekessel | Q27: Erdgas | R27: GuD | S27: 0.4048 | T27: OPSD (2020) | U27: 12 | V27: 11.5 | W27: 10.005 | X27: 40.69 | Y27: 136.45393
A28: Ja | B28: SEE965660903200 | C28: =VLOOKUP(B28,Tabelle3!A:C,2,FALSE) -> Nord | D28: In Betrieb | E28: DREWAG - Stadtwerke Dresden GmbH | F28: Gasmotoren-Heizkraftwerk Dresden-Reick - Aggregat I | G28: 01277 | H28: Dresden | I28: Liebstädter Straße 1 | J28: Sachsen | K28: 44610 | L28: Erdgas | M28: Erdgas, Erdölgas | N28: Erdgas | O28: Ja | P28: Verbrennungsmotor | Q28: Erdgas | R28: GuD | S28: 0.63 | T28: Annahme basierend auf DIW (2014) | U28: 11.76 | V28: 11.5 | W28: 10.005 | X28: 40.69 | Y28: 88.213254
A29: Ja | B29: SEE985036646654 | C29: =VLOOKUP(B29,Tabelle3!A:C,2,FALSE) -> Nord | D29: In Betrieb | E29: DREWAG - Stadtwerke Dresden GmbH | F29: Gasmotoren-Heizkraftwerk Dresden-Reick - Aggregat II | G29: 01277 | H29: Dresden | I29: Liebstädter Straße 1 | J29: Sachsen | K29: 44610 | L29: Erdgas | M29: Erdgas, Erdölgas | N29: Erdgas | O29: Ja | P29: Verbrennungsmotor | Q29: Erdgas | R29: GuD | S29: 0.63 | T29: Annahme basierend auf DIW (2014) | U29: 11.76 | V29: 11.5 | W29: 10.005 | X29: 40.69 | Y29: 88.213254
A30: Ja | B30: SEE930647914081 | C30: =VLOOKUP(B30,Tabelle3!A:C,2,FALSE) -> Nord | D30: In Betrieb | E30: DREWAG - Stadtwerke Dresden GmbH | F30: Gasmotoren-Heizkraftwerk Dresden-Reick - Aggregat III | G30: 01277 | H30: Dresden | I30: Liebstädter Straße 1 | J30: Sachsen | K30: 44610 | L30: Erdgas | M30: Erdgas, Erdölgas | N30: Erdgas | O30: Ja | P30: Verbrennungsmotor | Q30: Erdgas | R30: GuD | S30: 0.63 | T30: Annahme basierend auf DIW (2014) | U30: 11.76 | V30: 11.5 | W30: 10.005 | X30: 40.69 | Y30: 88.213254
A31: Ja | B31: SEE962395118756 | C31: =VLOOKUP(B31,Tabelle3!A:C,2,FALSE) -> Nord | D31: In Betrieb | E31: DREWAG - Stadtwerke Dresden GmbH | F31: Gasmotoren-Heizkraftwerk Dresden-Reick - Aggregat IV | G31: 01277 | H31: Dresden | I31: Liebstädter Straße 1 | J31: Sachsen | K31: 44610 | L31: Erdgas | M31: Erdgas, Erdölgas | N31: Erdgas | O31: Ja | P31: Verbrennungsmotor | Q31: Erdgas | R31: GuD | S31: 0.63 | T31: Annahme basierend auf DIW (2014) | U31: 11.76 | V31: 11.5 | W31: 10.005 | X31: 40.69 | Y31: 88.213254
A32: Ja | B32: SEE924562445072 | C32: =VLOOKUP(B32,Tabelle3!A:C,2,FALSE) -> Nord | D32: In Betrieb | E32: DREWAG - Stadtwerke Dresden GmbH | F32: Gasmotoren-Heizkraftwerk Dresden-Reick - Aggregat V | G32: 01277 | H32: Dresden | I32: Liebstädter Straße 1 | J32: Sachsen | K32: 44610 | L32: Erdgas | M32: Erdgas, Erdölgas | N32: Erdgas | O32: Ja | P32: Verbrennungsmotor | Q32: Erdgas | R32: GuD | S32: 0.63 | T32: Annahme basierend auf DIW (2014) | U32: 11.76 | V32: 11.5 | W32: 10.005 | X32: 40.69 | Y32: 88.213254
A33: Ja | B33: SEE963438570067 | C33: =VLOOKUP(B33,Tabelle3!A:C,2,FALSE) -> Nord | D33: In Betrieb | E33: DREWAG - Stadtwerke Dresden GmbH | F33: Gasmotoren-Heizkraftwerk Dresden-Reick - Aggregat VI | G33: 01277 | H33: Dresden | I33: Liebstädter Straße 1 | J33: Sachsen | K33: 44610 | L33: Erdgas | M33: Erdgas, Erdölgas | N33: Erdgas | O33: Ja | P33: Verbrennungsmotor | Q33: Erdgas | R33: GuD | S33: 0.63 | T33: Annahme basierend auf DIW (2014) | U33: 11.76 | V33: 11.5 | W33: 10.005 | X33: 40.69 | Y33: 88.213254
A34: Ja | B34: SEE939899660715 | C34: =VLOOKUP(B34,Tabelle3!A:C,2,FALSE) -> Nord | D34: In Betrieb | E34: DREWAG - Stadtwerke Dresden GmbH | F34: Gasmotoren-Heizkraftwerk Dresden-Reick - Aggregat VII | G34: 01277 | H34: Dresden | I34: Liebstädter Straße 1 | J34: Sachsen | K34: 44610 | L34: Erdgas | M34: Erdgas, Erdölgas | N34: Erdgas | O34: Ja | P34: Verbrennungsmotor | Q34: Erdgas | R34: GuD | S34: 0.63 | T34: Annahme basierend auf DIW (2014) | U34: 11.76 | V34: 11.5 | W34: 10.005 | X34: 40.69 | Y34: 88.213254
A35: Ja | B35: SEE923793340132 | C35: =VLOOKUP(B35,Tabelle3!A:C,2,FALSE) -> Nord | D35: In Betrieb | E35: DREWAG - Stadtwerke Dresden GmbH | F35: Gasmotoren-Heizkraftwerk Dresden-Reick - Aggregat VIII | G35: 01277 | H35: Dresden | I35: Liebstädter Straße 1 | J35: Sachsen | K35: 44610 | L35: Erdgas | M35: Erdgas, Erdölgas | N35: Erdgas | O35: Ja | P35: Verbrennungsmotor | Q35: Erdgas | R35: GuD | S35: 0.63 | T35: Annahme basierend auf DIW (2014) | U35: 11.76 | V35: 11.5 | W35: 10.005 | X35: 40.69 | Y35: 88.213254
A36: Ja | B36: SEE967194778880 | C36: =VLOOKUP(B36,Tabelle3!A:C,2,FALSE) -> Nord | D36: In Betrieb | E36: DREWAG - Stadtwerke Dresden GmbH | F36: GT1 | G36: 01159 | H36: Dresden | I36: Oederaner Straße 21 | J36: Sachsen | K36: 34803 | L36: Erdgas | M36: Erdgas, Erdölgas | N36: Erdgas | O36: Ja | P36: Gasturbinen mit nachgeschalteter Dampfturbine | Q36: Erdgas | R36: Gasturbine | S36: 0.5175 | T36: OPSD (2020) | U36: 65 | V36: 62 | W36: 53.94 | X36: 40.69 | Y36: 106.56396
A37: Ja | B37: SEE968254365774 | C37: =VLOOKUP(B37,Tabelle3!A:C,2,FALSE) -> Nord | D37: In Betrieb | E37: DREWAG - Stadtwerke Dresden GmbH | F37: GT2 | G37: 01159 | H37: Dresden | I37: Oederaner Straße 21 | J37: Sachsen | K37: 34772 | L37: Erdgas | M37: Erdgas, Erdölgas | N37: Erdgas | O37: Ja | P37: Gasturbinen mit nachgeschalteter Dampfturbine | Q37: Erdgas | R37: Gasturbine | S37: 0.5175 | T37: OPSD (2020) | U37: 65 | V37: 62 | W37: 53.94 | X37: 40.69 | Y37: 106.56396
A38: Ja | B38: SEE901410470721 | C38: =VLOOKUP(B38,Tabelle3!A:C,2,FALSE) -> Nord | D38: In Betrieb | E38: DREWAG - Stadtwerke Dresden GmbH | F38: GT3 | G38: 01159 | H38: Dresden | I38: Oederaner Straße 21 | J38: Sachsen | K38: 34787 | L38: Erdgas | M38: Erdgas, Erdölgas | N38: Erdgas | O38: Ja | P38: Gasturbinen mit nachgeschalteter Dampfturbine | Q38: Erdgas | R38: Gasturbine | S38: 0.5175 | T38: OPSD (2020) | U38: 65 | V38: 62 | W38: 53.94 | X38: 40.69 | Y38: 106.56396
A39: Ja | B39: SEE950477241393 | C39: =VLOOKUP(B39,Tabelle3!A:C,2,FALSE) -> Nord | D39: In Betrieb | E39: DREWAG - Stadtwerke Dresden GmbH | F39: DT | G39: 01159 | H39: Dresden | I39: Oederaner Straße 21 | J39: Sachsen | K39: 34810 | L39: Erdgas | M39: Erdgas, Erdölgas | N39: Erdgas | O39: Ja | P39: Gegendruckmaschine mit Entnahme | Q39: Erdgas | R39: GuD | S39: 0.407 | T39: Annahme basierend auf DIW (2014) | U39: 75 | V39: 74 | W39: 64.38 | X39: 40.69 | Y39: 135.72445
A40: Ja | B40: SEE932949912406 | C40: Nord | D40: In Betrieb | E40: e.distherm Energielösungen GmbH | F40: Energiezentrale Notstrom | G40: 12529 | H40: Schönefeld | I40: Hugo-Eckener-Allee 12 | J40: Brandenburg | K40: 40368 | L40: Mineralölprodukte | M40: Heizöl, leicht | N40: Mineralölprodukte | O40: Nein | P40: Verbrennungsmotor | Q40: Öl | R40: Öl | S40: 0.406 | T40: Annahme basierend auf DIW (2014) | U40: 14.52 | V40: 14.52 | W40: 12.342 | X40: 95.89 | Y40: 285.00985
...

Sheet Tabelle3
A1: MaStR-ID | B1: ÜNB | C1: Betreiber | D1: Kraftwerksname | E1: Blockname | F1: Energieträger | G1: Technologie | H1: KWK | I1: PLZ | J1: Ort | K1: Bundesland | L1: Inbetriebnahmejahr | M1: Status aktuell | N1: Nettonennleistung [MW] 31.12.2023 | O1: Leistung [MW] 2037 | P1: Energieträger 2037 | Q1: Leistung [MW] 2045 | R1: Energieträger 2045
A2: NV | B2: Süd | C2: EnBW Energie Baden-Wuerttemberg AG | D2: Heizkraftwerk Altbach/Deizisau | E2: ALT HKW 3 | F2: Erdgas | G2: GuD | H2: ja | I2: 73776 | J2: Altbach | K2: Baden-Wuerttemberg | L2: 2026 | M2: In Bau | N2: 710 | O2: 710 | P2: Erdgas/Wasserstoff | Q2: 710 | R2: Wasserstoff
A3: SEE907667929555 | B3: Nord | C3: DREWAG Stadtwerke Dresden GmbH | D3: HKW Dresden-Nord | E3: HKW Dresden-Nord | F3: Erdgas | G3: Gasturbine | H3: ja | I3: 01099 | J3: Dresden | K3: Sachsen | L3: 2018 | M3: In Betrieb | N3: 11.5 | O3: 11.5 | P3: Erdgas/Wasserstoff | Q3: 11.5 | R3: Wasserstoff
A4: SEE967194778880 | B4: Nord | C4: DREWAG Stadtwerke Dresden GmbH | D4: HKW Dresden-Nossener Bruecke | E4: GT1 | F4: Erdgas | G4: GuD | H4: ja | I4: 01169 | J4: Dresden | K4: Sachsen | L4: 1995 | M4: In Betrieb | N4: 62 | O4: 62 | P4: Erdgas/Wasserstoff | Q4: 62 | R4: Wasserstoff
A5: SEE968254365774 | B5: Nord | C5: DREWAG Stadtwerke Dresden GmbH | D5: HKW Dresden-Nossener Bruecke | E5: GT2 | F5: Erdgas | G5: GuD | H5: ja | I5: 01169 | J5: Dresden | K5: Sachsen | L5: 1995 | M5: In Betrieb | N5: 62 | O5: 62 | P5: Erdgas/Wasserstoff | Q5: 62 | R5: Wasserstoff
A6: SEE901410470721 | B6: Nord | C6: DREWAG Stadtwerke Dresden GmbH | D6: HKW Dresden-Nossener Bruecke | E6: GT3 | F6: Erdgas | G6: GuD | H6: ja | I6: 01169 | J6: Dresden | K6: Sachsen | L6: 1995 | M6: In Betrieb | N6: 62 | O6: 62 | P6: Erdgas/Wasserstoff | Q6: 62 | R6: Wasserstoff
A7: SEE950477241393 | B7: Nord | C7: DREWAG Stadtwerke Dresden GmbH | D7: HKW Dresden-Nossener Bruecke | E7: DT | F7: Erdgas | G7: GuD | H7: ja | I7: 01169 | J7: Dresden | K7: Sachsen | L7: 1995 | M7: In Betrieb | N7: 74 | O7: 74 | P7: Erdgas/Wasserstoff | Q7: 74 | R7: Wasserstoff
A8: SEE965660903200 | B8: Nord | C8: DREWAG - Stadtwerke Dresden GmbH | D8: Gasmotoren-HKW Dresden-Reick | E8: Aggregat 1 | F8: Erdgas | G8: Verbrennungsmotor | H8: ja | I8: 01237 | J8: Dresden | K8: Sachsen | L8: 2022 | M8: In Betrieb | N8: 11.5 | O8: 11.5 | P8: Erdgas/Wasserstoff | Q8: 11.5 | R8: Wasserstoff
A9: SEE985036646654 | B9: Nord | C9: DREWAG - Stadtwerke Dresden GmbH | D9: Gasmotoren-HKW Dresden-Reick | E9: Aggregat 2 | F9: Erdgas | G9: Verbrennungsmotor | H9: ja | I9: 01237 | J9: Dresden | K9: Sachsen | L9: 2022 | M9: In Betrieb | N9: 11.5 | O9: 11.5 | P9: Erdgas/Wasserstoff | Q9: 11.5 | R9: Wasserstoff
A10: SEE930647914081 | B10: Nord | C10: DREWAG - Stadtwerke Dresden GmbH | D10: Gasmotoren-HKW Dresden-Reick | E10: Aggregat 3 | F10: Erdgas | G10: Verbrennungsmotor | H10: ja | I10: 01237 | J10: Dresden | K10: Sachsen | L10: 2022 | M10: In Betrieb | N10: 11.5 | O10: 11.5 | P10: Erdgas/Wasserstoff | Q10: 11.5 | R10: Wasserstoff
A11: SEE962395118756 | B11: Nord | C11: DREWAG - Stadtwerke Dresden GmbH | D11: Gasmotoren-HKW Dresden-Reick | E11: Aggregat 4 | F11: Erdgas | G11: Verbrennungsmotor | H11: ja | I11: 01237 | J11: Dresden | K11: Sachsen | L11: 2022 | M11: In Betrieb | N11: 11.5 | O11: 11.5 | P11: Erdgas/Wasserstoff | Q11: 11.5 | R11: Wasserstoff
A12: SEE911764038249 | B12: Süd | C12: Uniper Kraftwerke GmbH | D12: Franken 1 | E12: DT 1 | F12: Erdgas | G12: Dampfturbine | H12: nein | I12: 90449 | J12: Nuernberg | K12: Bayern | L12: 1973 | M12: In Betrieb | N12: 383 | O12: 383 | P12: Erdgas/Wasserstoff | Q12: 383 | R12: Wasserstoff
A13: SEE948129095272 | B13: Süd | C13: Uniper Kraftwerke GmbH | D13: Ulrich Hartmann (Irsching) | E13: 4 | F13: Erdgas | G13: GuD | H13: nein | I13: 85088 | J13: Vohburg | K13: Bayern | L13: 2011 | M13: In Betrieb | N13: 561 | O13: 561 | P13: Erdgas/Wasserstoff | Q13: 561 | R13: Wasserstoff
A14: SEE933021962319 | B14: Nord | C14: Uniper Kraftwerke GmbH | D14: Waldeck 2 | E14: Maschine 5 | F14: Wasser | G14: Pumpspeicher | H14: nein | I14: 34549 | J14: Edertal Hemfurth-Edersee | K14: Hessen | L14: 1974 | M14: In Betrieb | N14: 240 | O14: 240 | P14: Wasser | Q14: 240 | R14: Wasser
A15: SEE996080766151 | B15: Nord | C15: Uniper Kraftwerke GmbH | D15: Waldeck 2 | E15: Maschine 6 | F15: Wasser | G15: Pumpspeicher | H15: nein | I15: 34549 | J15: Edertal Hemfurth-Edersee | K15: Hessen | L15: 1974 | M15: In Betrieb | N15: 240 | O15: 240 | P15: Wasser | Q15: 240 | R15: Wasser
A16: SEE974201537415 | B16: Nord | C16: Uniper Kraftwerke GmbH | D16: Huntorf | E16: NV | F16: Erdgas | G16: Gasturbine | H16: nein | I16: 26931 | J16: Elsfleth | K16: Niedersachsen | L16: 1978 | M16: In Betrieb | N16: 321 | O16: 321 | P16: Erdgas/Wasserstoff | Q16: 321 | R16: Wasserstoff
A17: SEE924562445072 | B17: Nord | C17: DREWAG - Stadtwerke Dresden GmbH | D17: Gasmotoren-HKW Dresden-Reick | E17: Aggregat 5 | F17: Erdgas | G17: Verbrennungsmotor | H17: ja | I17: 01237 | J17: Dresden | K17: Sachsen | L17: 2022 | M17: In Betrieb | N17: 11.5 | O17: 11.5 | P17: Erdgas/Wasserstoff | Q17: 11.5 | R17: Wasserstoff
A18: SEE963438570067 | B18: Nord | C18: DREWAG - Stadtwerke Dresden GmbH | D18: Gasmotoren-HKW Dresden-Reick | E18: Aggregat 6 | F18: Erdgas | G18: Verbrennungsmotor | H18: ja | I18: 01237 | J18: Dresden | K18: Sachsen | L18: 2022 | M18: In Betrieb | N18: 11.5 | O18: 11.5 | P18: Erdgas/Wasserstoff | Q18: 11.5 | R18: Wasserstoff
A19: SEE939899660715 | B19: Nord | C19: DREWAG - Stadtwerke Dresden GmbH | D19: Gasmotoren-HKW Dresden-Reick | E19: Aggregat 7 | F19: Erdgas | G19: Verbrennungsmotor | H19: ja | I19: 01237 | J19: Dresden | K19: Sachsen | L19: 2022 | M19: In Betrieb | N19: 11.5 | O19: 11.5 | P19: Erdgas/Wasserstoff | Q19: 11.5 | R19: Wasserstoff
A20: SEE923793340132 | B20: Nord | C20: DREWAG - Stadtwerke Dresden GmbH | D20: Gasmotoren-HKW Dresden-Reick | E20: Aggregat 8 | F20: Erdgas | G20: Verbrennungsmotor | H20: ja | I20: 01237 | J20: Dresden | K20: Sachsen | L20: 2022 | M20: In Betrieb | N20: 11.5 | O20: 11.5 | P20: Erdgas/Wasserstoff | Q20: 11.5 | R20: Wasserstoff
A21: SEE989200392347 | B21: Nord | C21: Sachsenmilch Leppersdorf GmbH | D21: Kraftwerk Sachsenmilch Leppersdorf Wachau | E21: GT 1 | F21: Erdgas | G21: GuD | H21: ja | I21: 01454 | J21: Wachau | K21: Sachsen | L21: 2014 | M21: In Betrieb | N21: 14.89 | O21: 14.89 | P21: Erdgas/Wasserstoff | Q21: 14.89 | R21: Wasserstoff
A22: SEE927473609168 | B22: Süd | C22: InfraServ GmbH & Co. Gendorf KG | D22: Industriepark Werk Gendorf | E22: NV | F22: Erdgas | G22: GuD | H22: ja | I22: 84508 | J22: Burgkirchen | K22: Bayern | L22: 2002 | M22: In Betrieb | N22: 73.1 | O22: 73.1 | P22: Erdgas/Wasserstoff | Q22: 73.1 | R22: Wasserstoff
A23: SEE966920434281 | B23: Nord | C23: Stadtwerke Flensburg GmbH | D23: Heizkraftwerk FL | E23: Gasturbine 12 | F23: Erdgas | G23: GuD | H23: ja | I23: 24939 | J23: Flensburg | K23: Schleswig-Holstein | L23: 2016 | M23: In Betrieb | N23: 50.1 | O23: 50.1 | P23: Erdgas/Wasserstoff | Q23: 50.1 | R23: Wasserstoff
A24: SEE937878572653 | B24: Süd | C24: Donau-Wasserkraft AG | D24: PSW Langenprozelten | E24: E F2 | F24: Wasser | G24: Pumpspeicher | H24: nein | I24: 97737 | J24: Gemünden | K24: Bayern | L24: 1974 | M24: In Betrieb | N24: 82 | O24: 82 | P24: Wasser | Q24: 82 | R24: Wasser
A25: SEE991939746742 | B25: Süd | C25: Donau-Wasserkraft AG | D25: PSW Langenprozelten | E25: E F1 | F25: Wasser | G25: Pumpspeicher | H25: nein | I25: 97737 | J25: Gemünden | K25: Bayern | L25: 1974 | M25: In Betrieb | N25: 82 | O25: 82 | P25: Wasser | Q25: 82 | R25: Wasser
A26: SEE967069763799 | B26: Süd | C26: Stadtwerke Muenchen GmbH | D26: Leitzach 1 | E26: 1 | F26: Wasser | G26: Pumpspeicher | H26: nein | I26: 83620 | J26: Vagen | K26: Bayern | L26: 1983 | M26: In Betrieb | N26: 48 | O26: 48 | P26: Wasser | Q26: 48 | R26: Wasser
A27: SEE932484697615 | B27: Süd | C27: Stadtwerke Muenchen GmbH | D27: Leitzach 2 | E27: M22 | F27: Wasser | G27: Pumpspeicher | H27: nein | I27: 83620 | J27: Vagen | K27: Bayern | L27: 1960 | M27: In Betrieb | N27: 22 | O27: 22 | P27: Wasser | Q27: 22 | R27: Wasser
A28: SEE953508633730 | B28: Süd | C28: Stadtwerke Muenchen GmbH | D28: Leitzach 2 | E28: 2 | F28: Wasser | G28: Pumpspeicher | H28: nein | I28: 83620 | J28: Vagen | K28: Bayern | L28: 1960 | M28: In Betrieb | N28: 22 | O28: 22 | P28: Wasser | Q28: 22 | R28: Wasser
A29: SEE979861364876 | B29: Nord | C29: K+S Minerals and Agriculture GmbH | D29: Wintershall | E29: Kraftwerk WI DT 2.1 | F29: Erdgas | G29: Dampfturbine | H29: ja | I29: 36266 | J29: Heringen | K29: Hessen | L29: 2009 | M29: In Betrieb | N29: 52.7 | O29: 52.7 | P29: Erdgas/Wasserstoff | Q29: 52.7 | R29: Wasserstoff
A30: SEE973250051972 | B30: Nord | C30: Georg-August-Universität Göttingen Stiftung Öffentlichen Rechts | D30: HKW Goettingen | E30: NV | F30: Erdgas | G30: Gasturbine | H30: ja | I30: 37075 | J30: Göttingen | K30: Niedersachsen | L30: 1998 | M30: In Betrieb | N30: 18.8 | O30: 18.8 | P30: Erdgas/Wasserstoff | Q30: 18.8 | R30: Wasserstoff
A31: SEE912764206645 | B31: Süd | C31: Erlanger Stadtwerke AG | D31: HKW Erlangen | E31: GuD I | F31: Erdgas | G31: GuD | H31: ja | I31: 91052 | J31: Erlangen | K31: Bayern | L31: 2005 | M31: In Betrieb | N31: 21.6 | O31: 21.6 | P31: Erdgas/Wasserstoff | Q31: 21.6 | R31: Wasserstoff
A32: SEE904662075126 | B32: Nord | C32: Sachsenmilch Leppersdorf GmbH | D32: Kraftwerk Sachsenmilch Leppersdorf Wachau | E32: GT 2 | F32: Erdgas | G32: GuD | H32: ja | I32: 01454 | J32: Wachau | K32: Sachsen | L32: 2014 | M32: In Betrieb | N32: 14.89 | O32: 14.89 | P32: Erdgas/Wasserstoff | Q32: 14.89 | R32: Wasserstoff
A33: SEE917568874298 | B33: Nord | C33: Sachsenmilch Leppersdorf GmbH | D33: Kraftwerk Sachsenmilch Leppersdorf Wachau | E33: DT | F33: Erdgas | G33: GuD | H33: ja | I33: 01454 | J33: Wachau | K33: Sachsen | L33: 2014 | M33: In Betrieb | N33: 5.9 | O33: 5.9 | P33: Erdgas/Wasserstoff | Q33: 5.9 | R33: Wasserstoff
A34: SEE914224312040 | B34: Nord | C34: Global Foundries Dresden Module Two LLC | D34: Gasmotoren Blockheizkraftwerk I | E34: Generator 1 | F34: Erdgas | G34: Verbrennungsmotor | H34: ja | I34: 01468 | J34: Moritzburg | K34: Sachsen | L34: 1998 | M34: In Betrieb | N34: 3.9 | O34: 3.9 | P34: Erdgas/Wasserstoff | Q34: 3.9 | R34: Wasserstoff
A35: SEE932664806912 | B35: Nord | C35: Global Foundries Dresden Module Two LLC | D35: Gasmotoren Blockheizkraftwerk I | E35: Generator 2 | F35: Erdgas | G35: Verbrennungsmotor | H35: ja | I35: 01468 | J35: Moritzburg | K35: Sachsen | L35: 1998 | M35: In Betrieb | N35: 3.9 | O35: 3.9 | P35: Erdgas/Wasserstoff | Q35: 3.9 | R35: Wasserstoff
A36: SEE987679030500 | B36: Nord | C36: Global Foundries Dresden Module Two LLC | D36: Gasmotoren Blockheizkraftwerk I | E36: Generator 3 | F36: Erdgas | G36: Verbrennungsmotor | H36: ja | I36: 01468 | J36: Moritzburg | K36: Sachsen | L36: 1998 | M36: In Betrieb | N36: 3.9 | O36: 3.9 | P36: Erdgas/Wasserstoff | Q36: 3.9 | R36: Wasserstoff
A37: SEE923918497345 | B37: Nord | C37: Global Foundries Dresden Module Two LLC | D37: Gasmotoren Blockheizkraftwerk I | E37: Generator 4 | F37: Erdgas | G37: Verbrennungsmotor | H37: ja | I37: 01468 | J37: Moritzburg | K37: Sachsen | L37: 1998 | M37: In Betrieb | N37: 3.9 | O37: 3.9 | P37: Erdgas/Wasserstoff | Q37: 3.9 | R37: Wasserstoff
A38: SEE903406002589 | B38: Nord | C38: Global Foundries Dresden Module Two LLC | D38: Gasmotoren Blockheizkraftwerk I | E38: Generator 5 | F38: Erdgas | G38: Verbrennungsmotor | H38: ja | I38: 01468 | J38: Moritzburg | K38: Sachsen | L38: 1998 | M38: In Betrieb | N38: 3.9 | O38: 3.9 | P38: Erdgas/Wasserstoff | Q38: 3.9 | R38: Wasserstoff
A39: SEE956441736957 | B39: Nord | C39: Global Foundries Dresden Module Two LLC | D39: Gasmotoren Blockheizkraftwerk I | E39: Generator 6 | F39: Erdgas | G39: Verbrennungsmotor | H39: ja | I39: 01468 | J39: Moritzburg | K39: Sachsen | L39: 1998 | M39: In Betrieb | N39: 3.9 | O39: 3.9 | P39: Erdgas/Wasserstoff | Q39: 3.9 | R39: Wasserstoff
A40: SEE972526098451 | B40: Süd | C40: Stadtwerke Würzburg AG | D40: Heizkraftwerke an der Friedensbruecke | E40: TSIII | F40: Erdgas | G40: GuD | H40: ja | I40: 97080 | J40: Wuerzburg | K40: Bayern | L40: 1971 | M40: In Betrieb | N40: 23 | O40: 23 | P40: Erdgas/Wasserstoff | Q40: 23 | R40: Wasserstoff
...
